Workbook
Name consulta: MOVIMENTACOES!$J$294:$K$302
Name produto: PRODUTOS!$A$1:$H$239

Sheet PRODUTOS
A1: Código do Produto | B1: Nome do Item | C1: Fornecedor | D1: Unidade de Medida | E1: Categoria | F1: Marca | G1: Localizção | H1: Descrição do Produto | I1: Column 9
A2: 200000018 | B2: Algodão Hidrófilo Bola 100gr | C2: SIGBP | D2: UN | E2: CONSUMO | F2: Nathy | G2: ARMARIO (A) | H2: Algodão Hidrófilo Bola 100g Farol é ideal para a higienização e assepsia da pele, remoção de maquiagem, esmalte e higiene do bebê. Composto por fibras 100% algodão purificadas e alvejadas, seu formato em bolas facilita a utilização, tornando-o prático para diversos procedimentos de cuidados pessoais e médicos. Adequado para ambientes hospitalares e uso doméstico, garante alta absorção e suavidade. Características: Fibras 100% algodão purificadas e alvejadas; Formato em bolas que facilita a utilização; Ideal para higienização e assepsia da pele, remoção de maquiagem e esmaltes; Adequado para uso médico-hospitalar. Especificações Técnicas: Material: 100% algodão; Peso: 100g; Registro ANVISA: 10341660006.
A3: 200000001 | B3: LIXA D'AGUA 150 | C3: CORDEIRO MAQUINAS E FERRAMENTAS | D3: UN | E3: CONSUMO | F3: BOSCH | G3: A(6-3) | H3: C423 Contém 25 folhas um pct, do tamanho 225 mm x 275 mm Composição: Costado de papel látex á prova d'água, óxido de alumínio e adesivos. Garantia, grão e validade: vide costado de luxa. Amazenar em lugar seco e ventilado.
A4: 200007285 | B4: LIXA D'MADEIRA 120 | C4: CORDEIRO MAQUINAS E FERRAMENTAS | D4: UN | E4: CONSUMO | F4: BOSCH | G4: A(6-4) | H4: D411 Contém 25 folhas um pct, do tamanho 225 mm x 275 mm Composição: Costado de papel látex á prova d'água, óxido de alumínio e adesivos. Garantia, grão e validade: vide costado de luxa. Amazenar em lugar seco e ventilado.
A5: 200000006 | B5: OLEO MINERAL 70PS | C5: CASASLEO | D5: UN | E5: CONSUMO | F5: NÃO INFORMADO | G5: Faltando
A6: 200002700 | B6: THINNER / LIMPEZA E ACABAMENTO 900ML | C6: CORDEIRO MAQUINAS E FERRAMENTAS | D6: UN | E6: CONSUMO | F6: ITAQUA | G6: A(10-1) | H6: FAB: 11/2024 VAL: 3 ANOS IT 16 (thinner-multiuso) IT 800 (thinner - diluição) IT 37 (thinner acabamento automotivo)
A7: 200026827 | B7: TRINCHA 3 | C7: CORDEIRO MAQUINAS E FERRAMENTAS | D7: UN | E7: CONSUMO | F7: ATLAS | G7: A(6-4) | H7: PCT COM 12 UNIDADE Aspectos: Suas cerdas mistas são suaves, macias, proporcionam boa absorção e retenção de tinta, evitam desperdício de tempo e dinheiro. Coberturas e acabamentos uniformes, deslizamento suave e material resistente são algumas das principais características deste pincel.
A8: 200024290 | B8: TRINCHA 3/4 | C8: CORDEIRO MAQUINAS E FERRAMENTAS | D8: UN | E8: CONSUMO | F8: ATLAS | G8: A(6-3) | H8: PCT COM 12 UNIDADE Trincha para Pintura Média 3/4" Atlas possui cerdas brancas selecionadas que oferecem uma melhor performance no momento da pintura. O produto é ideal no uso de verniz e stain para você deixar a reforma ou o acabamento da sua decoração do jeito que você gosta.
A9: 200065892 | B9: FITA ISOLANTE 18MMX20M COR PRETA | C9: SIGBP | D9: UN | E9: CONSUMO | G9: ARMARIO (B) | H9: FITA ISOLANTE 18MMX20M COR PRETA
A10: 200076172 | B10: LUVA DE VINIL G(9) COM 100 UND | C10: SIGBP | D10: UN | E10: EPI | F10: NOBRE | G10: ARMARIO (B) | H10: LUVA DE VINIL G(9) COM 100 UND
A11: 200052414 | B11: LUVA LATEX M(8) COM 100 UND | C11: SIGBP | D11: UN | E11: EPI | F11: NOBRE | G11: ARMARIO (B) | H11: LUVA DE VINIL M(8) COM 100 UND
A12: 200052413 | B12: LUVA LATEX P COM 100 UND | C12: SIGBP | D12: UN | E12: EPI | F12: HEALTHCARE | G12: ARMARIO (B) | H12: LUVA PARA PROCEDIMENTO NÃO CURÚRGICO EM LATEX COM PO TAMANHO P COM 100 UNIDADES
A13: 200037491 | B13: MASCARA CIRURGICA TRIPLA | C13: SIGBP | D13: UN | E13: EPI | F13: NOBRE | G13: ARMARIO (B) | H13: MASCARA CIRURGICA DESCARTAVEL COM 3 CAMADAS RETANGULAR COM ELASTICO EMBALAGEM COM 50UN
A14: 200075793 | B14: MASCARA DE PROTEÇÃO PFF2 FILTRO N95 COM VALVULA SUPER SAFETY (azul) | C14: SIGBP | D14: PCT | E14: EPI | F14: AIRPROT | G14: ARMARIO (B) | H14: MASCARA DE PROTEÇÃO PFF2 FILTRO N95 COM VALVULA SUPER SAFETY CA
A15: 200061889 | B15: MASCARA DE PROTEÇÃO PFF2 FILTRO N95( BRANCA) | C15: SIGBP | D15: UN | E15: EPI | F15: 2 - NUTRIEX 5 - CHIKOOL | G15: ARMARIO (B) | H15: MASCARA DE PROTEÇÃO PFF2 FILTRO N95
A16: 200070939 | B16: MASCARA DE PROTEÇÃO PFR95 FILTRO N95 (PRETA) | C16: SIGBP | D16: UN | E16: EPI
A17: 200065969 | B17: OCULOS DE PROTEÇÃO JAGUAR | C17: SIGBP | D17: UN | E17: EPI | F17: KAPIPSO epi | G17: ARMARIO (B) | H17: OCULOS DE PROTEÇÃO POLICARBONATO INCOLOR TIPO CARBOGRAFITE
A18: 200052480 | B18: PROTETOR AURICULAR DE SILICONE TIPO PLUG | C18: SIGBP | D18: UN | E18: EPI | F18: SUPERMEDY | G18: ARMARIO (B) | H18: PROTETOR AURICULAR DE SILICONE TIPO PLUG
A19: 200052481 | B19: PROTETOR AURICULAR TIPO CONCHA | C19: SIGBP | D19: CX | E19: EPI | F19: CONFORTPLUS | G19: ARMARIO (B) | H19: ABAFADOR DE RUIDO TIPO CONCHA
A20: 200000700 | B20: TOUCA DESCARTAVEL PACOTE COM 100 UN | C20: SIGBP | D20: UN | E20: EPI | G20: ARMARIO (A) | H20: A Touca Descartável da Descarpack é um artigo médico utilizado para impedir a queda de cabelos em locais que precisam de alta limpeza e, assim, evitar possíveis contaminações ou acidentes. A touca é voltada para uso por profissionais de áreas diversas. Características e detalhes: * Fabricada em Tecido Não Tecido (TNT) 100% polipropileno; * Possui elástico revestido que garante maior vedação e conforto; * Confeccionada em material que permite a respiração do couro cabeludo; * Tamanho único; * Não estéril, descartável e de uso único. Indicações de uso: A Touca Descartável da Descarpack é indicada para uso em ambientes médicos e hospitalares – hospitais, clínicas, laboratórios, farmácias ou clínicas odontológicas. Pode ser usada também por profissionais das áreas de alimentação e nutrição. Especificações do produto: Pacote com 100 unidades. Cor: branca. Ref.: 0093201.
A21: 207218574 | B21: LUVA EPI ALGODÃO MALHA PIGMENTADA PRETA | C21: SIGBP | D21: UN | E21: EPI | G21: ARMARIO (B)
A22: 200043606 | B22: PASTA OFICIO EM PAPELAO COM TRILHO 250X340MM | C22: SIGBP | D22: UN | E22: EXPEDIENTE
A23: 200038284 | B23: ABRAÇADEIRA DE NYLON 100X2,5MM | C23: SIGBP | D23: UN | E23: EXPEDIENTE | G23: ARMARIO (B) | H23: ABRAÇADEIRA DE NYLON 100X2,5MM Pacote com 100unidade
A24: 200036752 | B24: ALCOOL 1LT | C24: SIGBP | D24: UN | E24: EXPEDIENTE | F24: BELLOBELLA INDUSTRIA DE COSMETICOS - 7 OUTRO - 1 OUTRO - 1 | G24: Faltando | H24: ALCOOL ETILICO A 70% DE 1LT
A25: 200069551 | B25: ALFINETE MARCADOR DE MAPA 8MM TIPO BOLA EM PLASTICO 50UN | C25: SIGBP | D25: CX | E25: EXPEDIENTE | F25: BACCHI | G25: ARMARIO (A) | H25: ALFINETE MARCADOR DE MAPA 8MM TIPO BOLA EM PLASTICO 50UN
A26: 200043234 | B26: ALFINETE PARA COSTURA CABO FINO Nº29 | C26: SIGBP | D26: CX | E26: EXPEDIENTE | F26: BACCHI | G26: ARMARIO (A) | H26: ALFINETE NIQUELADO, NÚMERO 29, 50 GRAMAS, MARCA BACCHI. PARA COSTURA
A27: 200056827 | B27: BORRACHA ESCOLAR BRANCA 34X23X8 | C27: SIGBP | D27: UN | E27: EXPEDIENTE | F27: PREMIER | G27: Faltando | H27: BORRACHA ESCOLAR BRANCA 34X23X8
A28: 200040799 | B28: CAIXA ARQUIVO MORTO EM POLIONDA MED (380X175X290) MM NA COR AMARELA | C28: SIGBP | D28: UN | E28: EXPEDIENTE | G28: B(2-3) | H28: CAIXA ARQUIVO MORTO EM POLIONDA MED (380X175X290) MM NA COR AMARELA
A29: 200036202 | B29: CANETA ESFEROGRAFICA PONTA MEDIA COR AZUL | C29: SIGBP | D29: CX | E29: EXPEDIENTE | F29: COMPACTOR ECONOMIC | G29: ARMARIO (A) | H29: CANETA ESFEROGRAFICA PONTA MEDIA COR AZUL
A30: 200036488 | B30: CANETA MARCADOR PERMANENTE PONTA 2.0mm | C30: SIGBP | D30: UN | E30: EXPEDIENTE | H30: marcador para retro projetor permanete ponta media 2.0mm
A31: 200038199 | B31: CANETA MARCADOR PERMANENTE PONTA GROSSA PRETO | C31: SIGBP | D31: UN | E31: EXPEDIENTE | F31: MASTERPRINT
A32: 200031692 | B32: CANETA PARA RETROPROJETOR FINA | C32: SIGBP | D32: UN | E32: EXPEDIENTE | H32: CANETA MARCADOR PERMANENTE PONTA GROSSA PRETO e AZUL(200031692)
A33: 200036201 | B33: CANETA ESFEROGRAFICA PONTA MEDIA COR PRETA | C33: SIGBP | D33: UN | E33: EXPEDIENTE | F33: COMPACTOR ECONOMIC | G33: ARMARIO (A-1) | H33: CANETA ESFEROGRAFICA PONTA MEDIA COR PRETA
A34: 200038178 | B34: CARTOLINA GRAMATURA 50X66CM DE 150G | C34: SIGBP | D34: UN | E34: EXPEDIENTE | G34: ARMARIO (A) | H34: CARTOLINA GRAMATURA 50X66CM DE 150G
A35: 200036489 | B35: CLIPS NIQUELADO Nº 1 COM 100 UN | C35: SIGBP | D35: CX | E35: EXPEDIENTE | F35: BACCHI | G35: ARMARIO (A) | H35: CLIPS NIQUELADO N°1 COM 100UND
A36: 200036490 | B36: CLIPS NIQUELADO Nº 2 COM 100 UN | C36: SIGBP | D36: CX | E36: EXPEDIENTE | F36: ECCOCLIPS | G36: ARMARIO (A) | H36: CLIPS NIQUELADO Nº 2 COM 100 UN
A37: 200037413 | B37: CLIPS NIQUELADO Nº 3 COM 50 UN | C37: SIGBP | D37: CX | E37: EXPEDIENTE | F37: ECCOCLIPS | G37: ARMARIO (A) | H37: CLIPS NIQUELADO Nº 3 COM 50 UN
A38: 200039379 | B38: CLIPS NIQUELADO Nº 8 COM 25 UN | C38: SIGBP | D38: CX | E38: EXPEDIENTE | G38: ARMARIO (A) | H38: CLIPS NIQUELADO Nº 8 COM 25 UN
A39: 200036793 | B39: COLHER DESCARTAVEL 12CM COM 50 UNIDADES | C39: SIGBP | D39: PCT | E39: EXPEDIENTE | G39: ARMARIO (B)
A40: 200036792 | B40: GARFO DESCARTAVEL 15CM COM 50 UNIDADES | C40: SIGBP | D40: PCT | E40: EXPEDIENTE | G40: ARMARIO (B)
...

Sheet MOVIMENTACOES
A1: Data | B1: ANO | C1: Código do Produto | D1: Nome do Produto | E1: Tipo | F1: Quantidade | G1: Local/Profissional | H1: OBS | I1: Coluna 1
B2: =TEXT(A2, "yyyy-mm") -> 1899-12 | D2: =IFERROR(VLOOKUP(C2,produto,2,FALSE), "Produto não encontrado") -> Produto não encontrado
A3: 46175 | B3: =TEXT(A3, "yyyy-mm") -> 2026-06 | C3: 200000088 | D3: =IFERROR(VLOOKUP(C3,produto,2,FALSE), "Produto não encontrado") -> (MTP-10)MALHA ORTOPEDICA TUBULAR 10CM | E3: Entrada | F3: 2 | G3: Devolveu Curso
A4: 46175 | B4: =TEXT(A4, "yyyy-mm") -> 2026-06 | C4: 200000066 | D4: =IFERROR(VLOOKUP(C4,produto,2,FALSE), "Produto não encontrado") -> ATADURA GESSADA 15cm x 3m, cx com 20 und | E4: Entrada | F4: 2 | G4: Devolveu Curso
A5: 46175 | B5: =TEXT(A5, "yyyy-mm") -> 2026-06 | C5: 200000081 | D5: =IFERROR(VLOOKUP(C5,produto,2,FALSE), "Produto não encontrado") -> ATADURA GESSADA 20cm x 2m, cx com 10 und | E5: Entrada | F5: 1 | G5: Devolveu Curso
A6: 46171 | B6: =TEXT(A6, "yyyy-mm") -> 2026-05 | C6: 200000088 | D6: =IFERROR(VLOOKUP(C6,produto,2,FALSE), "Produto não encontrado") -> (MTP-10)MALHA ORTOPEDICA TUBULAR 10CM | E6: Saída | F6: 1 | G6: Ribamar / Saida para o curso | H6: Curso TOP
A7: 46171 | B7: =TEXT(A7, "yyyy-mm") -> 2026-05 | C7: 200000096 | D7: =IFERROR(VLOOKUP(C7,produto,2,FALSE), "Produto não encontrado") -> RESINA RIGIDA PARA LAMINAÇÃO | E7: Saída | F7: 1 | G7: Ribamar / Saida para o curso | H7: Curso TOP
A8: 46170 | B8: =TEXT(A8, "yyyy-mm") -> 2026-05 | C8: 200000088 | D8: =IFERROR(VLOOKUP(C8,produto,2,FALSE), "Produto não encontrado") -> (MTP-10)MALHA ORTOPEDICA TUBULAR 10CM | E8: Saída | F8: 1 | G8: Ribamar / Saida para o curso | H8: Curso TOP
A9: 46168 | B9: =TEXT(A9, "yyyy-mm") -> 2026-05 | C9: 200000082 | D9: =IFERROR(VLOOKUP(C9,produto,2,FALSE), "Produto não encontrado") -> VALVULA DE SUCÇÃO EM BORRACHA | E9: Saída | F9: 1 | G9: Ribamar / Saida para o curso | H9: Curso TOP
A10: 46168 | B10: =TEXT(A10, "yyyy-mm") -> 2026-05 | C10: 200000081 | D10: =IFERROR(VLOOKUP(C10,produto,2,FALSE), "Produto não encontrado") -> ATADURA GESSADA 20cm x 2m, cx com 10 und | E10: Saída | F10: 1 | G10: Ribamar / Saida para o curso | H10: Curso TOP
A11: 46168 | B11: =TEXT(A11, "yyyy-mm") -> 2026-05 | C11: 200000066 | D11: =IFERROR(VLOOKUP(C11,produto,2,FALSE), "Produto não encontrado") -> ATADURA GESSADA 15cm x 3m, cx com 20 und | E11: Saída | F11: 1 | G11: Ribamar / Saida para o curso | H11: Curso TOP
A12: 46164 | B12: =TEXT(A12, "yyyy-mm") -> 2026-05 | C12: 200000097 | D12: =IFERROR(VLOOKUP(C12,produto,2,FALSE), "Produto não encontrado") -> SILICONE SPRAY 300ML | E12: Saída | F12: 1 | G12: Ribamar / Saida para o curso | H12: Curso TOP
A13: 46163 | B13: =TEXT(A13, "yyyy-mm") -> 2026-05 | C13: 200085859 | D13: =IFERROR(VLOOKUP(C13,produto,2,FALSE), "Produto não encontrado") -> PE SACH COM DEDOS DIREITO | E13: Saída | F13: 1 | G13: Ribamar / Saida para o curso | H13: Curso TOP
A14: 46163 | B14: =TEXT(A14, "yyyy-mm") -> 2026-05 | C14: 200085861 | D14: =IFERROR(VLOOKUP(C14,produto,2,FALSE), "Produto não encontrado") -> PE SACH COM DEDOS ESQUERDO | E14: Saída | F14: 1 | G14: Ribamar / Saida para o curso | H14: Curso TOP
A15: 46163 | B15: =TEXT(A15, "yyyy-mm") -> 2026-05 | C15: 200000083 | D15: =IFERROR(VLOOKUP(C15,produto,2,FALSE), "Produto não encontrado") -> MANTA FIBRA DE VIDRO | E15: Saída | F15: 1 | G15: Ribamar / Saida para o curso | H15: Curso TOP
A16: 46163 | B16: =TEXT(A16, "yyyy-mm") -> 2026-05 | C16: 200000095 | D16: =IFERROR(VLOOKUP(C16,produto,2,FALSE), "Produto não encontrado") -> ENDURECEDOR PARA RESINA | E16: Saída | F16: 1 | G16: Ribamar / Saida para o curso | H16: Curso TOP
A17: 46163 | B17: =TEXT(A17, "yyyy-mm") -> 2026-05 | C17: 200000096 | D17: =IFERROR(VLOOKUP(C17,produto,2,FALSE), "Produto não encontrado") -> RESINA RIGIDA PARA LAMINAÇÃO | E17: Saída | F17: 1 | G17: Ribamar / Saida para o curso | H17: Curso TOP
... A23: 46161 | B23: =TEXT(A23, "yyyy-mm") -> 2026-05 | C23: 200000066 | D23: =IFERROR(VLOOKUP(C23,produto,2,FALSE), "Produto não encontrado") -> ATADURA GESSADA 15cm x 3m, cx com 20 und | E23: Saída | F23: 1 | G23: Juliano / Saida para o curso | H23: Curso TOP
A24: 46156 | B24: =TEXT(A24, "yyyy-mm") -> 2026-05 | C24: 021000012 | D24: =IFERROR(VLOOKUP(C24,produto,2,FALSE), "Produto não encontrado") -> ESTOFAMENTO DE ASSENTO | E24: Saída | F24: 1
A25: 46156 | B25: =TEXT(A25, "yyyy-mm") -> 2026-05 | C25: 026000034 | D25: =IFERROR(VLOOKUP(C25,produto,2,FALSE), "Produto não encontrado") -> ESTOFAMENTO DE ENCOSTO | E25: Saída | F25: 1
A26: 46155 | B26: =TEXT(A26, "yyyy-mm") -> 2026-05 | C26: 200033068 | D26: =IFERROR(VLOOKUP(C26,produto,2,FALSE), "Produto não encontrado") -> PAPEL SULFITE A4 210 X 297MM 75G BRANCO MULTIUSO PACOTE COM 500 FLS | E26: Saída | F26: 1
A27: 46155 | B27: =TEXT(A27, "yyyy-mm") -> 2026-05 | C27: 200036189 | D27: =IFERROR(VLOOKUP(C27,produto,2,FALSE), "Produto não encontrado") -> COPO DESCARTAVEL 180ML | E27: Saída | F27: 1 | G27: Jucimeire Lins da Silva
A28: 46154 | B28: =TEXT(A28, "yyyy-mm") -> 2026-05 | C28: 200085970 | D28: =IFERROR(VLOOKUP(C28,produto,2,FALSE), "Produto não encontrado") -> COLA DE CONTATO MULTIUSO DE 2,8KG | E28: Saída | F28: 1
A29: 46150 | B29: =TEXT(A29, "yyyy-mm") -> 2026-05 | C29: 200036189 | D29: =IFERROR(VLOOKUP(C29,produto,2,FALSE), "Produto não encontrado") -> COPO DESCARTAVEL 180ML | E29: Saída | F29: 1 | G29: Expediente
A30: 46149 | B30: =TEXT(A30, "yyyy-mm") -> 2026-05 | C30: 200000065 | D30: =IFERROR(VLOOKUP(C30,produto,2,FALSE), "Produto não encontrado") -> ATADURA GESSADA 20cm x 4m, cx com 20 und | E30: Saída | F30: 1 | G30: RIBAMAR
A31: 46148 | B31: =TEXT(A31, "yyyy-mm") -> 2026-05 | C31: 200000054 | D31: =IFERROR(VLOOKUP(C31,produto,2,FALSE), "Produto não encontrado") -> FITA DE BORDA 1,5 x 2,5 x 1mm | E31: Saída | F31: 1 | G31: SARAH TO
A32: 46148 | B32: =TEXT(A32, "yyyy-mm") -> 2026-05 | C32: 200036577 | D32: =IFERROR(VLOOKUP(C32,produto,2,FALSE), "Produto não encontrado") -> GRAMPEADOR | E32: Entrada | F32: 2 | G32: Almox. OFORT
A33: 46148 | B33: =TEXT(A33, "yyyy-mm") -> 2026-05 | C33: 200043606 | D33: =IFERROR(VLOOKUP(C33,produto,2,FALSE), "Produto não encontrado") -> PASTA OFICIO EM PAPELAO COM TRILHO 250X340MM | E33: Entrada | F33: 10 | G33: Almox. OFORT
A34: 46148 | B34: =TEXT(A34, "yyyy-mm") -> 2026-05 | C34: 200070939 | D34: =IFERROR(VLOOKUP(C34,produto,2,FALSE), "Produto não encontrado") -> MASCARA DE PROTEÇÃO PFR95 FILTRO N95 (PRETA) | E34: Entrada | F34: 5 | G34: Almox. OFORT
A35: 46148 | B35: =TEXT(A35, "yyyy-mm") -> 2026-05 | C35: 200033068 | D35: =IFERROR(VLOOKUP(C35,produto,2,FALSE), "Produto não encontrado") -> PAPEL SULFITE A4 210 X 297MM 75G BRANCO MULTIUSO PACOTE COM 500 FLS | E35: Entrada | F35: 6 | G35: Almox. OFORT
A36: 46148 | B36: =TEXT(A36, "yyyy-mm") -> 2026-05 | C36: 200036793 | D36: =IFERROR(VLOOKUP(C36,produto,2,FALSE), "Produto não encontrado") -> COLHER DESCARTAVEL 12CM COM 50 UNIDADES | E36: Entrada | F36: 3 | G36: Almox. OFORT
A37: 46148 | B37: =TEXT(A37, "yyyy-mm") -> 2026-05 | C37: 200036792 | D37: =IFERROR(VLOOKUP(C37,produto,2,FALSE), "Produto não encontrado") -> GARFO DESCARTAVEL 15CM COM 50 UNIDADES | E37: Entrada | F37: 3 | G37: Almox. OFORT
A38: 46148 | B38: =TEXT(A38, "yyyy-mm") -> 2026-05 | C38: 200036791 | D38: =IFERROR(VLOOKUP(C38,produto,2,FALSE), "Produto não encontrado") -> PAPEL GUARDANAPO DE 20X22CM COM 50 FOLHAS | E38: Entrada | F38: 3 | G38: Almox. OFORT
A39: 46148 | B39: =TEXT(A39, "yyyy-mm") -> 2026-05 | C39: 200009230 | D39: =IFERROR(VLOOKUP(C39,produto,2,FALSE), "Produto não encontrado") -> PRATO DESCARTAVEL 12CM FUNDO | E39: Entrada | F39: 3 | G39: Almox. OFORT
A40: 46148 | B40: =TEXT(A40, "yyyy-mm") -> 2026-05 | C40: 200036793 | D40: =IFERROR(VLOOKUP(C40,produto,2,FALSE), "Produto não encontrado") -> COLHER DESCARTAVEL 12CM COM 50 UNIDADES | E40: Entrada | F40: 3 | G40: Almox. OFORT
... A46: 46169 | B46: =TEXT(A46, "yyyy-mm") -> 2026-05 | C46: 200001302 | D46: =IFERROR(VLOOKUP(C46,produto,2,FALSE), "Produto não encontrado") -> FORRAÇÃO ADESIVO 3M | E46: Entrada | F46: 5 | G46: compra da igreja
A47: 46169 | B47: =TEXT(A47, "yyyy-mm") -> 2026-05 | C47: 200000027 | D47: =IFERROR(VLOOKUP(C47,produto,2,FALSE), "Produto não encontrado") -> PLACA TERMOPLASTICA - ORFIT ECO NATUREL 45 x 60cm x 3.2mm MINI Perforated | E47: Entrada | F47: 15 | G47: compra da igreja
A48: 46169 | B48: =TEXT(A48, "yyyy-mm") -> 2026-05 | C48: 200000054 | D48: =IFERROR(VLOOKUP(C48,produto,2,FALSE), "Produto não encontrado") -> FITA DE BORDA 1,5 x 2,5 x 1mm | E48: Saída | F48: 1 | G48: SARAH TO
A49: 46139 | B49: =TEXT(A49, "yyyy-mm") -> 2026-04 | C49: 200000027 | D49: =IFERROR(VLOOKUP(C49,produto,2,FALSE), "Produto não encontrado") -> PLACA TERMOPLASTICA - ORFIT ECO NATUREL 45 x 60cm x 3.2mm MINI Perforated | E49: Saída | F49: 3 | G49: SARAH TO
A50: 46147 | B50: =TEXT(A50, "yyyy-mm") -> 2026-05 | C50: 200000080 | D50: =IFERROR(VLOOKUP(C50,produto,2,FALSE), "Produto não encontrado") -> ATADURA GESSADA 15cm x 2m, cx com 10 und | E50: Saída | F50: 1 | G50: VANDELEY
...

Sheet ESTOQUE ATUAL
A1: Código do Produto | B1: Nome do Item | C1: Categoria | D1: Column 10 | E1: Entradas Totais | F1: Saídas Totais | G1: Saldo Atual | H1: Situação | I1: Fornecedor
A2: 200000018 | B2: =VLOOKUP(A2,produto,2,0) -> Algodão Hidrófilo Bola 100gr | C2: =IFERROR(VLOOKUP(A2,PRODUTOS!A:E,5,FALSE), "Categoria não encontrada") -> CONSUMO | D2: =IFERROR(VLOOKUP(A2,PRODUTOS!A:E,4,FALSE), "Categoria não encontrada") -> UN | E2: =SUMIFS(MOVIMENTACOES!F:F,MOVIMENTACOES!C:C,A2,MOVIMENTACOES!E:E,"Entrada") -> 2 | F2: =SUMIFS(MOVIMENTACOES!F:F,MOVIMENTACOES!C:C,A2,MOVIMENTACOES!E:E,"Saída") -> 0 | G2: =E2-F2 -> 2 | H2: =IF(G2=0, "Faltando", IF(G2<=3, "Atenção", "OK")) -> Atenção | I2: =VLOOKUP(A2, PRODUTOS!A:H, 3, FALSE) -> SIGBP
A3: 200065892 | B3: =VLOOKUP(A3,produto,2,0) -> FITA ISOLANTE 18MMX20M COR PRETA | C3: =IFERROR(VLOOKUP(A3,PRODUTOS!A:E,5,FALSE), "Categoria não encontrada") -> CONSUMO | D3: =IFERROR(VLOOKUP(A3,PRODUTOS!A:E,4,FALSE), "Categoria não encontrada") -> UN | E3: =SUMIFS(MOVIMENTACOES!F:F,MOVIMENTACOES!C:C,A3,MOVIMENTACOES!E:E,"Entrada") -> 3 | F3: =SUMIFS(MOVIMENTACOES!F:F,MOVIMENTACOES!C:C,A3,MOVIMENTACOES!E:E,"Saída") -> 2 | G3: =E3-F3 -> 1 | H3: =IF(G3=0, "Faltando", IF(G3<=3, "Atenção", "OK")) -> Atenção | I3: =VLOOKUP(A3, PRODUTOS!A:H, 3, FALSE) -> SIGBP
A4: 200037491 | B4: =VLOOKUP(A4,produto,2,0) -> MASCARA CIRURGICA TRIPLA | C4: =IFERROR(VLOOKUP(A4,PRODUTOS!A:E,5,FALSE), "Categoria não encontrada") -> EPI | D4: =IFERROR(VLOOKUP(A4,PRODUTOS!A:E,4,FALSE), "Categoria não encontrada") -> UN | E4: =SUMIFS(MOVIMENTACOES!F:F,MOVIMENTACOES!C:C,A4,MOVIMENTACOES!E:E,"Entrada") -> 10 | F4: =SUMIFS(MOVIMENTACOES!F:F,MOVIMENTACOES!C:C,A4,MOVIMENTACOES!E:E,"Saída") -> 8 | G4: =E4-F4 -> 2 | H4: =IF(G4=0, "Faltando", IF(G4<=3, "Atenção", "OK")) -> Atenção | I4: =VLOOKUP(A4, PRODUTOS!A:H, 3, FALSE) -> SIGBP
A5: 200065969 | B5: =VLOOKUP(A5,produto,2,0) -> OCULOS DE PROTEÇÃO JAGUAR | C5: =IFERROR(VLOOKUP(A5,PRODUTOS!A:E,5,FALSE), "Categoria não encontrada") -> EPI | D5: =IFERROR(VLOOKUP(A5,PRODUTOS!A:E,4,FALSE), "Categoria não encontrada") -> UN | E5: =SUMIFS(MOVIMENTACOES!F:F,MOVIMENTACOES!C:C,A5,MOVIMENTACOES!E:E,"Entrada") -> 4 | F5: =SUMIFS(MOVIMENTACOES!F:F,MOVIMENTACOES!C:C,A5,MOVIMENTACOES!E:E,"Saída") -> 2 | G5: =E5-F5 -> 2 | H5: =IF(G5=0, "Faltando", IF(G5<=3, "Atenção", "OK")) -> Atenção | I5: =VLOOKUP(A5, PRODUTOS!A:H, 3, FALSE) -> SIGBP
A6: 200052480 | B6: =VLOOKUP(A6,produto,2,0) -> PROTETOR AURICULAR DE SILICONE TIPO PLUG | C6: =IFERROR(VLOOKUP(A6,PRODUTOS!A:E,5,FALSE), "Categoria não encontrada") -> EPI | D6: =IFERROR(VLOOKUP(A6,PRODUTOS!A:E,4,FALSE), "Categoria não encontrada") -> UN | E6: =SUMIFS(MOVIMENTACOES!F:F,MOVIMENTACOES!C:C,A6,MOVIMENTACOES!E:E,"Entrada") -> 1 | F6: =SUMIFS(MOVIMENTACOES!F:F,MOVIMENTACOES!C:C,A6,MOVIMENTACOES!E:E,"Saída") -> 0 | G6: =E6-F6 -> 1 | H6: =IF(G6=0, "Faltando", IF(G6<=3, "Atenção", "OK")) -> Atenção | I6: =VLOOKUP(A6, PRODUTOS!A:H, 3, FALSE) -> SIGBP
A7: 200052481 | B7: =VLOOKUP(A7,produto,2,0) -> PROTETOR AURICULAR TIPO CONCHA | C7: =IFERROR(VLOOKUP(A7,PRODUTOS!A:E,5,FALSE), "Categoria não encontrada") -> EPI | D7: =IFERROR(VLOOKUP(A7,PRODUTOS!A:E,4,FALSE), "Categoria não encontrada") -> CX | E7: =SUMIFS(MOVIMENTACOES!F:F,MOVIMENTACOES!C:C,A7,MOVIMENTACOES!E:E,"Entrada") -> 1 | F7: =SUMIFS(MOVIMENTACOES!F:F,MOVIMENTACOES!C:C,A7,MOVIMENTACOES!E:E,"Saída") -> 0 | G7: =E7-F7 -> 1 | H7: =IF(G7=0, "Faltando", IF(G7<=3, "Atenção", "OK")) -> Atenção | I7: =VLOOKUP(A7, PRODUTOS!A:H, 3, FALSE) -> SIGBP
A8: 200000700 | B8: =VLOOKUP(A8,produto,2,0) -> TOUCA DESCARTAVEL PACOTE COM 100 UN | C8: =IFERROR(VLOOKUP(A8,PRODUTOS!A:E,5,FALSE), "Categoria não encontrada") -> EPI | D8: =IFERROR(VLOOKUP(A8,PRODUTOS!A:E,4,FALSE), "Categoria não encontrada") -> UN | E8: =SUMIFS(MOVIMENTACOES!F:F,MOVIMENTACOES!C:C,A8,MOVIMENTACOES!E:E,"Entrada") -> 1 | F8: =SUMIFS(MOVIMENTACOES!F:F,MOVIMENTACOES!C:C,A8,MOVIMENTACOES!E:E,"Saída") -> 0 | G8: =E8-F8 -> 1 | H8: =IF(G8=0, "Faltando", IF(G8<=3, "Atenção", "OK")) -> Atenção | I8: =VLOOKUP(A8, PRODUTOS!A:H, 3, FALSE) -> SIGBP
A9: 200038284 | B9: =VLOOKUP(A9,produto,2,0) -> ABRAÇADEIRA DE NYLON 100X2,5MM | C9: =IFERROR(VLOOKUP(A9,PRODUTOS!A:E,5,FALSE), "Categoria não encontrada") -> EXPEDIENTE | D9: =IFERROR(VLOOKUP(A9,PRODUTOS!A:E,4,FALSE), "Categoria não encontrada") -> UN | E9: =SUMIFS(MOVIMENTACOES!F:F,MOVIMENTACOES!C:C,A9,MOVIMENTACOES!E:E,"Entrada") -> 2 | F9: =SUMIFS(MOVIMENTACOES!F:F,MOVIMENTACOES!C:C,A9,MOVIMENTACOES!E:E,"Saída") -> 1 | G9: =E9-F9 -> 1 | H9: =IF(G9=0, "Faltando", IF(G9<=3, "Atenção", "OK")) -> Atenção | I9: =VLOOKUP(A9, PRODUTOS!A:H, 3, FALSE) -> SIGBP
A10: 200069551 | B10: =VLOOKUP(A10,produto,2,0) -> ALFINETE MARCADOR DE MAPA 8MM TIPO BOLA EM PLASTICO 50UN | C10: =IFERROR(VLOOKUP(A10,PRODUTOS!A:E,5,FALSE), "Categoria não encontrada") -> EXPEDIENTE | D10: =IFERROR(VLOOKUP(A10,PRODUTOS!A:E,4,FALSE), "Categoria não encontrada") -> CX | E10: =SUMIFS(MOVIMENTACOES!F:F,MOVIMENTACOES!C:C,A10,MOVIMENTACOES!E:E,"Entrada") -> 3 | F10: =SUMIFS(MOVIMENTACOES!F:F,MOVIMENTACOES!C:C,A10,MOVIMENTACOES!E:E,"Saída") -> 1 | G10: =E10-F10 -> 2 | H10: =IF(G10=0, "Faltando", IF(G10<=3, "Atenção", "OK")) -> Atenção | I10: =VLOOKUP(A10, PRODUTOS!A:H, 3, FALSE) -> SIGBP
A11: 200043234 | B11: =VLOOKUP(A11,produto,2,0) -> ALFINETE PARA COSTURA CABO FINO Nº29 | C11: =IFERROR(VLOOKUP(A11,PRODUTOS!A:E,5,FALSE), "Categoria não encontrada") -> EXPEDIENTE | D11: =IFERROR(VLOOKUP(A11,PRODUTOS!A:E,4,FALSE), "Categoria não encontrada") -> CX | E11: =SUMIFS(MOVIMENTACOES!F:F,MOVIMENTACOES!C:C,A11,MOVIMENTACOES!E:E,"Entrada") -> 3 | F11: =SUMIFS(MOVIMENTACOES!F:F,MOVIMENTACOES!C:C,A11,MOVIMENTACOES!E:E,"Saída") -> 0 | G11: =E11-F11 -> 3 | H11: =IF(G11=0, "Faltando", IF(G11<=3, "Atenção", "OK")) -> Atenção | I11: =VLOOKUP(A11, PRODUTOS!A:H, 3, FALSE) -> SIGBP
A12: 200040799 | B12: =VLOOKUP(A12,produto,2,0) -> CAIXA ARQUIVO MORTO EM POLIONDA MED (380X175X290) MM NA COR AMARELA | C12: =IFERROR(VLOOKUP(A12,PRODUTOS!A:E,5,FALSE), "Categoria não encontrada") -> EXPEDIENTE | D12: =IFERROR(VLOOKUP(A12,PRODUTOS!A:E,4,FALSE), "Categoria não encontrada") -> UN | E12: =SUMIFS(MOVIMENTACOES!F:F,MOVIMENTACOES!C:C,A12,MOVIMENTACOES!E:E,"Entrada") -> 4 | F12: =SUMIFS(MOVIMENTACOES!F:F,MOVIMENTACOES!C:C,A12,MOVIMENTACOES!E:E,"Saída") -> 2 | G12: =E12-F12 -> 2 | H12: =IF(G12=0, "Faltando", IF(G12<=3, "Atenção", "OK")) -> Atenção | I12: =VLOOKUP(A12, PRODUTOS!A:H, 3, FALSE) -> SIGBP
A13: 200036941 | B13: =VLOOKUP(A13,produto,2,0) -> COLA BRANCA BASTAO 10G | C13: =IFERROR(VLOOKUP(A13,PRODUTOS!A:E,5,FALSE), "Categoria não encontrada") -> EXPEDIENTE | D13: =IFERROR(VLOOKUP(A13,PRODUTOS!A:E,4,FALSE), "Categoria não encontrada") -> UN | E13: =SUMIFS(MOVIMENTACOES!F:F,MOVIMENTACOES!C:C,A13,MOVIMENTACOES!E:E,"Entrada") -> 2 | F13: =SUMIFS(MOVIMENTACOES!F:F,MOVIMENTACOES!C:C,A13,MOVIMENTACOES!E:E,"Saída") -> 0 | G13: =E13-F13 -> 2 | H13: =IF(G13=0, "Faltando", IF(G13<=3, "Atenção", "OK")) -> Atenção | I13: =VLOOKUP(A13, PRODUTOS!A:H, 3, FALSE) -> SIGBP
A14: 200036189 | B14: =VLOOKUP(A14,produto,2,0) -> COPO DESCARTAVEL 180ML | C14: =IFERROR(VLOOKUP(A14,PRODUTOS!A:E,5,FALSE), "Categoria não encontrada") -> EXPEDIENTE | D14: =IFERROR(VLOOKUP(A14,PRODUTOS!A:E,4,FALSE), "Categoria não encontrada") -> UN | E14: =SUMIFS(MOVIMENTACOES!F:F,MOVIMENTACOES!C:C,A14,MOVIMENTACOES!E:E,"Entrada") -> 43 | F14: =SUMIFS(MOVIMENTACOES!F:F,MOVIMENTACOES!C:C,A14,MOVIMENTACOES!E:E,"Saída") -> 40 | G14: =E14-F14 -> 3 | H14: =IF(G14=0, "Faltando", IF(G14<=3, "Atenção", "OK")) -> Atenção | I14: =VLOOKUP(A14, PRODUTOS!A:H, 3, FALSE) -> SIGBP
... A27: 200000408 | B27: =VLOOKUP(A27,produto,2,0) -> LENÇOL DESCARTAVEL 50 x 70 mm | C27: =IFERROR(VLOOKUP(A27,PRODUTOS!A:E,5,FALSE), "Categoria não encontrada") -> LIMPEZA | D27: =IFERROR(VLOOKUP(A27,PRODUTOS!A:E,4,FALSE), "Categoria não encontrada") -> UN | E27: =SUMIFS(MOVIMENTACOES!F:F,MOVIMENTACOES!C:C,A27,MOVIMENTACOES!E:E,"Entrada") -> 2 | F27: =SUMIFS(MOVIMENTACOES!F:F,MOVIMENTACOES!C:C,A27,MOVIMENTACOES!E:E,"Saída") -> 1 | G27: =E27-F27 -> 1 | H27: =IF(G27=0, "Faltando", IF(G27<=3, "Atenção", "OK")) -> Atenção | I27: =VLOOKUP(A27, PRODUTOS!A:H, 3, FALSE) -> SIGBP
A28: 200000019 | B28: =VLOOKUP(A28,produto,2,0) -> Papel Toalha Interfolhado | C28: =IFERROR(VLOOKUP(A28,PRODUTOS!A:E,5,FALSE), "Categoria não encontrada") -> LIMPEZA | D28: =IFERROR(VLOOKUP(A28,PRODUTOS!A:E,4,FALSE), "Categoria não encontrada") -> RL | E28: =SUMIFS(MOVIMENTACOES!F:F,MOVIMENTACOES!C:C,A28,MOVIMENTACOES!E:E,"Entrada") -> 3 | F28: =SUMIFS(MOVIMENTACOES!F:F,MOVIMENTACOES!C:C,A28,MOVIMENTACOES!E:E,"Saída") -> 0 | G28: =E28-F28 -> 3 | H28: =IF(G28=0, "Faltando", IF(G28<=3, "Atenção", "OK")) -> Atenção | I28: =VLOOKUP(A28, PRODUTOS!A:H, 3, FALSE) -> SIGBP
A29: 200070056 | B29: =VLOOKUP(A29,produto,2,0) -> PAPEL TOALHADE ROLHO | C29: =IFERROR(VLOOKUP(A29,PRODUTOS!A:E,5,FALSE), "Categoria não encontrada") -> LIMPEZA | D29: =IFERROR(VLOOKUP(A29,PRODUTOS!A:E,4,FALSE), "Categoria não encontrada") -> UN | E29: =SUMIFS(MOVIMENTACOES!F:F,MOVIMENTACOES!C:C,A29,MOVIMENTACOES!E:E,"Entrada") -> 1 | F29: =SUMIFS(MOVIMENTACOES!F:F,MOVIMENTACOES!C:C,A29,MOVIMENTACOES!E:E,"Saída") -> 0 | G29: =E29-F29 -> 1 | H29: =IF(G29=0, "Faltando", IF(G29<=3, "Atenção", "OK")) -> Atenção | I29: =VLOOKUP(A29, PRODUTOS!A:H, 3, FALSE) -> SIGBP
A30: 200061213 | B30: =VLOOKUP(A30,produto,2,0) -> SABONETE LIQUIDO CONCENTRADO 1L | C30: =IFERROR(VLOOKUP(A30,PRODUTOS!A:E,5,FALSE), "Categoria não encontrada") -> LIMPEZA | D30: =IFERROR(VLOOKUP(A30,PRODUTOS!A:E,4,FALSE), "Categoria não encontrada") -> UN | E30: =SUMIFS(MOVIMENTACOES!F:F,MOVIMENTACOES!C:C,A30,MOVIMENTACOES!E:E,"Entrada") -> 1 | F30: =SUMIFS(MOVIMENTACOES!F:F,MOVIMENTACOES!C:C,A30,MOVIMENTACOES!E:E,"Saída") -> 0 | G30: =E30-F30 -> 1 | H30: =IF(G30=0, "Faltando", IF(G30<=3, "Atenção", "OK")) -> Atenção | I30: =VLOOKUP(A30, PRODUTOS!A:H, 3, FALSE) -> SIGBP
A31: 200000054 | B31: =VLOOKUP(A31,produto,2,0) -> FITA DE BORDA 1,5 x 2,5 x 1mm | C31: =IFERROR(VLOOKUP(A31,PRODUTOS!A:E,5,FALSE), "Categoria não encontrada") -> MATERIAL T.O | D31: =IFERROR(VLOOKUP(A31,PRODUTOS!A:E,4,FALSE), "Categoria não encontrada") -> UN | E31: =SUMIFS(MOVIMENTACOES!F:F,MOVIMENTACOES!C:C,A31,MOVIMENTACOES!E:E,"Entrada") -> 5 | F31: =SUMIFS(MOVIMENTACOES!F:F,MOVIMENTACOES!C:C,A31,MOVIMENTACOES!E:E,"Saída") -> 3 | G31: =E31-F31 -> 2 | H31: =IF(G31=0, "Faltando", IF(G31<=3, "Atenção", "OK")) -> Atenção | I31: =VLOOKUP(A31, PRODUTOS!A:H, 3, FALSE) -> ARTICULATO
A32: 200000055 | B32: =VLOOKUP(A32,produto,2,0) -> PEÇA / MATERIAL PARA ORTESES tipo FORRAÇÃO AUTO-ADESIVA ESP | C32: =IFERROR(VLOOKUP(A32,PRODUTOS!A:E,5,FALSE), "Categoria não encontrada") -> MATERIAL T.O | D32: =IFERROR(VLOOKUP(A32,PRODUTOS!A:E,4,FALSE), "Categoria não encontrada") -> UN | E32: =SUMIFS(MOVIMENTACOES!F:F,MOVIMENTACOES!C:C,A32,MOVIMENTACOES!E:E,"Entrada") -> 3 | F32: =SUMIFS(MOVIMENTACOES!F:F,MOVIMENTACOES!C:C,A32,MOVIMENTACOES!E:E,"Saída") -> 1 | G32: =E32-F32 -> 2 | H32: =IF(G32=0, "Faltando", IF(G32<=3, "Atenção", "OK")) -> Atenção | I32: =VLOOKUP(A32, PRODUTOS!A:H, 3, FALSE) -> ARTICULATO
A33: 200000060 | B33: =VLOOKUP(A33,produto,2,0) -> VELCRO FEMEA 50mm VERMELHO | C33: =IFERROR(VLOOKUP(A33,PRODUTOS!A:E,5,FALSE), "Categoria não encontrada") -> MATERIAL T.O | D33: =IFERROR(VLOOKUP(A33,PRODUTOS!A:E,4,FALSE), "Categoria não encontrada") -> UN | E33: =SUMIFS(MOVIMENTACOES!F:F,MOVIMENTACOES!C:C,A33,MOVIMENTACOES!E:E,"Entrada") -> 1 | F33: =SUMIFS(MOVIMENTACOES!F:F,MOVIMENTACOES!C:C,A33,MOVIMENTACOES!E:E,"Saída") -> 0 | G33: =E33-F33 -> 1 | H33: =IF(G33=0, "Faltando", IF(G33<=3, "Atenção", "OK")) -> Atenção | I33: =VLOOKUP(A33, PRODUTOS!A:H, 3, FALSE) -> ARTICULATO
A34: 200000057 | B34: =VLOOKUP(A34,produto,2,0) -> VELCRO FEMEA 50mm AZUL MARINHO V182 | C34: =IFERROR(VLOOKUP(A34,PRODUTOS!A:E,5,FALSE), "Categoria não encontrada") -> MATERIAL T.O | D34: =IFERROR(VLOOKUP(A34,PRODUTOS!A:E,4,FALSE), "Categoria não encontrada") -> UN | E34: =SUMIFS(MOVIMENTACOES!F:F,MOVIMENTACOES!C:C,A34,MOVIMENTACOES!E:E,"Entrada") -> 2 | F34: =SUMIFS(MOVIMENTACOES!F:F,MOVIMENTACOES!C:C,A34,MOVIMENTACOES!E:E,"Saída") -> 1 | G34: =E34-F34 -> 1 | H34: =IF(G34=0, "Faltando", IF(G34<=3, "Atenção", "OK")) -> Atenção | I34: =VLOOKUP(A34, PRODUTOS!A:H, 3, FALSE) -> ARTICULATO
A35: 200000058 | B35: =VLOOKUP(A35,produto,2,0) -> VELCRO FEMEA 50mm Verde Escuro | C35: =IFERROR(VLOOKUP(A35,PRODUTOS!A:E,5,FALSE), "Categoria não encontrada") -> MATERIAL T.O | D35: =IFERROR(VLOOKUP(A35,PRODUTOS!A:E,4,FALSE), "Categoria não encontrada") -> UN | E35: =SUMIFS(MOVIMENTACOES!F:F,MOVIMENTACOES!C:C,A35,MOVIMENTACOES!E:E,"Entrada") -> 2 | F35: =SUMIFS(MOVIMENTACOES!F:F,MOVIMENTACOES!C:C,A35,MOVIMENTACOES!E:E,"Saída") -> 1 | G35: =E35-F35 -> 1 | H35: =IF(G35=0, "Faltando", IF(G35<=3, "Atenção", "OK")) -> Atenção | I35: =VLOOKUP(A35, PRODUTOS!A:H, 3, FALSE) -> ARTICULATO
A36: 200000064 | B36: =VLOOKUP(A36,produto,2,0) -> VELCRO FEMEA 50mm BEGE | C36: =IFERROR(VLOOKUP(A36,PRODUTOS!A:E,5,FALSE), "Categoria não encontrada") -> MATERIAL T.O | D36: =IFERROR(VLOOKUP(A36,PRODUTOS!A:E,4,FALSE), "Categoria não encontrada") -> UN | E36: =SUMIFS(MOVIMENTACOES!F:F,MOVIMENTACOES!C:C,A36,MOVIMENTACOES!E:E,"Entrada") -> 2 | F36: =SUMIFS(MOVIMENTACOES!F:F,MOVIMENTACOES!C:C,A36,MOVIMENTACOES!E:E,"Saída") -> 1 | G36: =E36-F36 -> 1 | H36: =IF(G36=0, "Faltando", IF(G36<=3, "Atenção", "OK")) -> Atenção | I36: =VLOOKUP(A36, PRODUTOS!A:H, 3, FALSE) -> ARTICULATO
A37: 200000062 | B37: =VLOOKUP(A37,produto,2,0) -> VELCRO FEMEA 50mm LARANJA V627 | C37: =IFERROR(VLOOKUP(A37,PRODUTOS!A:E,5,FALSE), "Categoria não encontrada") -> MATERIAL T.O | D37: =IFERROR(VLOOKUP(A37,PRODUTOS!A:E,4,FALSE), "Categoria não encontrada") -> UN | E37: =SUMIFS(MOVIMENTACOES!F:F,MOVIMENTACOES!C:C,A37,MOVIMENTACOES!E:E,"Entrada") -> 2 | F37: =SUMIFS(MOVIMENTACOES!F:F,MOVIMENTACOES!C:C,A37,MOVIMENTACOES!E:E,"Saída") -> 0 | G37: =E37-F37 -> 2 | H37: =IF(G37=0, "Faltando", IF(G37<=3, "Atenção", "OK")) -> Atenção | I37: =VLOOKUP(A37, PRODUTOS!A:H, 3, FALSE) -> ARTICULATO
A38: 200000059 | B38: =VLOOKUP(A38,produto,2,0) -> VELCRO FEMEA 50mm VINHO V328 | C38: =IFERROR(VLOOKUP(A38,PRODUTOS!A:E,5,FALSE), "Categoria não encontrada") -> MATERIAL T.O | D38: =IFERROR(VLOOKUP(A38,PRODUTOS!A:E,4,FALSE), "Categoria não encontrada") -> UN | E38: =SUMIFS(MOVIMENTACOES!F:F,MOVIMENTACOES!C:C,A38,MOVIMENTACOES!E:E,"Entrada") -> 2 | F38: =SUMIFS(MOVIMENTACOES!F:F,MOVIMENTACOES!C:C,A38,MOVIMENTACOES!E:E,"Saída") -> 1 | G38: =E38-F38 -> 1 | H38: =IF(G38=0, "Faltando", IF(G38<=3, "Atenção", "OK")) -> Atenção | I38: =VLOOKUP(A38, PRODUTOS!A:H, 3, FALSE) -> ARTICULATO
A39: 200000061 | B39: =VLOOKUP(A39,produto,2,0) -> VELCRO FEMEA 50mm AMARELO | C39: =IFERROR(VLOOKUP(A39,PRODUTOS!A:E,5,FALSE), "Categoria não encontrada") -> MATERIAL T.O | D39: =IFERROR(VLOOKUP(A39,PRODUTOS!A:E,4,FALSE), "Categoria não encontrada") -> UN | E39: =SUMIFS(MOVIMENTACOES!F:F,MOVIMENTACOES!C:C,A39,MOVIMENTACOES!E:E,"Entrada") -> 1 | F39: =SUMIFS(MOVIMENTACOES!F:F,MOVIMENTACOES!C:C,A39,MOVIMENTACOES!E:E,"Saída") -> 0 | G39: =E39-F39 -> 1 | H39: =IF(G39=0, "Faltando", IF(G39<=3, "Atenção", "OK")) -> Atenção | I39: =VLOOKUP(A39, PRODUTOS!A:H, 3, FALSE) -> ARTICULATO
A40: 200000023 | B40: =VLOOKUP(A40,produto,2,0) -> VELCRO FEMEA 50mm ROSA | C40: =IFERROR(VLOOKUP(A40,PRODUTOS!A:E,5,FALSE), "Categoria não encontrada") -> MATERIAL T.O | D40: =IFERROR(VLOOKUP(A40,PRODUTOS!A:E,4,FALSE), "Categoria não encontrada") -> UN | E40: =SUMIFS(MOVIMENTACOES!F:F,MOVIMENTACOES!C:C,A40,MOVIMENTACOES!E:E,"Entrada") -> 1 | F40: =SUMIFS(MOVIMENTACOES!F:F,MOVIMENTACOES!C:C,A40,MOVIMENTACOES!E:E,"Saída") -> 0 | G40: =E40-F40 -> 1 | H40: =IF(G40=0, "Faltando", IF(G40<=3, "Atenção", "OK")) -> Atenção | I40: =VLOOKUP(A40, PRODUTOS!A:H, 3, FALSE) -> SIGBP
A41: 200000050 | B41: =VLOOKUP(A41,produto,2,0) -> ORFICAST BLUE 300cm x 3cm FITA TERMOPLASTICA | C41: =IFERROR(VLOOKUP(A41,PRODUTOS!A:E,5,FALSE), "Categoria não encontrada") -> MATERIAL T.O | D41: =IFERROR(VLOOKUP(A41,PRODUTOS!A:E,4,FALSE), "Categoria não encontrada") -> UN | E41: =SUMIFS(MOVIMENTACOES!F:F,MOVIMENTACOES!C:C,A41,MOVIMENTACOES!E:E,"Entrada") -> 4 | F41: =SUMIFS(MOVIMENTACOES!F:F,MOVIMENTACOES!C:C,A41,MOVIMENTACOES!E:E,"Saída") -> 2 | G41: =E41-F41 -> 2 | H41: =IF(G41=0, "Faltando", IF(G41<=3, "Atenção", "OK")) -> Atenção | I41: =VLOOKUP(A41, PRODUTOS!A:H, 3, FALSE) -> EFECTIV
A42: 200000026 | B42: =VLOOKUP(A42,produto,2,0) -> PLACA TERMOPLASTICA - ORFIT ECO NATUREL 45 x 60 cm 2.4 mm | C42: =IFERROR(VLOOKUP(A42,PRODUTOS!A:E,5,FALSE), "Categoria não encontrada") -> MATERIAL T.O | D42: =IFERROR(VLOOKUP(A42,PRODUTOS!A:E,4,FALSE), "Categoria não encontrada") -> UN | E42: =SUMIFS(MOVIMENTACOES!F:F,MOVIMENTACOES!C:C,A42,MOVIMENTACOES!E:E,"Entrada") -> 7 | F42: =SUMIFS(MOVIMENTACOES!F:F,MOVIMENTACOES!C:C,A42,MOVIMENTACOES!E:E,"Saída") -> 6 | G42: =E42-F42 -> 1 | H42: =IF(G42=0, "Faltando", IF(G42<=3, "Atenção", "OK")) -> Atenção | I42: =VLOOKUP(A42, PRODUTOS!A:H, 3, FALSE) -> EFECTIV
A43: 200000098 | B43: =VLOOKUP(A43,produto,2,0) -> LAMINA SURFORM | C43: OFICINA | D43: =IFERROR(VLOOKUP(A43,PRODUTOS!A:E,4,FALSE), "Categoria não encontrada") | E43: =SUMIFS(MOVIMENTACOES!F:F,MOVIMENTACOES!C:C,A43,MOVIMENTACOES!E:E,"Entrada") -> 3 | F43: =SUMIFS(MOVIMENTACOES!F:F,MOVIMENTACOES!C:C,A43,MOVIMENTACOES!E:E,"Saída") -> 0 | G43: =E43-F43 -> 3 | H43: =IF(G43=0, "Faltando", IF(G43<=3, "Atenção", "OK")) -> Atenção | I43: =VLOOKUP(A43, PRODUTOS!A:H, 3, FALSE)
A44: 200000097 | B44: =VLOOKUP(A44,produto,2,0) -> SILICONE SPRAY 300ML | C44: =IFERROR(VLOOKUP(A44,PRODUTOS!A:E,5,FALSE), "Categoria não encontrada") -> OFICINA | D44: =IFERROR(VLOOKUP(A44,PRODUTOS!A:E,4,FALSE), "Categoria não encontrada") -> UN | E44: =SUMIFS(MOVIMENTACOES!F:F,MOVIMENTACOES!C:C,A44,MOVIMENTACOES!E:E,"Entrada") -> 6 | F44: =SUMIFS(MOVIMENTACOES!F:F,MOVIMENTACOES!C:C,A44,MOVIMENTACOES!E:E,"Saída") -> 3 | G44: =E44-F44 -> 3 | H44: =IF(G44=0, "Faltando", IF(G44<=3, "Atenção", "OK")) -> Atenção | I44: =VLOOKUP(A44, PRODUTOS!A:H, 3, FALSE) -> SIGBP
A45: 200044160 | B45: =VLOOKUP(A45,produto,2,0) -> DESENGRIPANTE SPRAY 300ML | C45: =IFERROR(VLOOKUP(A45,PRODUTOS!A:E,5,FALSE), "Categoria não encontrada") -> OFICINA | D45: =IFERROR(VLOOKUP(A45,PRODUTOS!A:E,4,FALSE), "Categoria não encontrada") -> UN | E45: =SUMIFS(MOVIMENTACOES!F:F,MOVIMENTACOES!C:C,A45,MOVIMENTACOES!E:E,"Entrada") -> 3 | F45: =SUMIFS(MOVIMENTACOES!F:F,MOVIMENTACOES!C:C,A45,MOVIMENTACOES!E:E,"Saída") -> 1 | G45: =E45-F45 -> 2 | H45: =IF(G45=0, "Faltando", IF(G45<=3, "Atenção", "OK")) -> Atenção | I45: =VLOOKUP(A45, PRODUTOS!A:H, 3, FALSE) -> SIGBP
A46: 200085970 | B46: =VLOOKUP(A46,produto,2,0) -> COLA DE CONTATO MULTIUSO DE 2,8KG | C46: =IFERROR(VLOOKUP(A46,PRODUTOS!A:E,5,FALSE), "Categoria não encontrada") -> OFICINA | D46: =IFERROR(VLOOKUP(A46,PRODUTOS!A:E,4,FALSE), "Categoria não encontrada") -> UN | E46: =SUMIFS(MOVIMENTACOES!F:F,MOVIMENTACOES!C:C,A46,MOVIMENTACOES!E:E,"Entrada") -> 12 | F46: =SUMIFS(MOVIMENTACOES!F:F,MOVIMENTACOES!C:C,A46,MOVIMENTACOES!E:E,"Saída") -> 10 | G46: =E46-F46 -> 2 | H46: =IF(G46=0, "Faltando", IF(G46<=3, "Atenção", "OK")) -> Atenção | I46: =VLOOKUP(A46, PRODUTOS!A:H, 3, FALSE) -> SIGBP
A47: 200000066 | B47: =VLOOKUP(A47,produto,2,0) -> ATADURA GESSADA 15cm x 3m, cx com 20 und | C47: =IFERROR(VLOOKUP(A47,PRODUTOS!A:E,5,FALSE), "Categoria não encontrada") -> ORTESES E PROTESES | D47: =IFERROR(VLOOKUP(A47,PRODUTOS!A:E,4,FALSE), "Categoria não encontrada") -> CX | E47: =SUMIFS(MOVIMENTACOES!F:F,MOVIMENTACOES!C:C,A47,MOVIMENTACOES!E:E,"Entrada") -> 12 | F47: =SUMIFS(MOVIMENTACOES!F:F,MOVIMENTACOES!C:C,A47,MOVIMENTACOES!E:E,"Saída") -> 9 | G47: =E47-F47 -> 3 | H47: =IF(G47=0, "Faltando", IF(G47<=3, "Atenção", "OK")) -> Atenção
A48: 200000065 | B48: =VLOOKUP(A48,produto,2,0) -> ATADURA GESSADA 20cm x 4m, cx com 20 und | C48: =IFERROR(VLOOKUP(A48,PRODUTOS!A:E,5,FALSE), "Categoria não encontrada") -> ORTESES E PROTESES | D48: =IFERROR(VLOOKUP(A48,PRODUTOS!A:E,4,FALSE), "Categoria não encontrada") -> CX | E48: =SUMIFS(MOVIMENTACOES!F:F,MOVIMENTACOES!C:C,A48,MOVIMENTACOES!E:E,"Entrada") -> 7 | F48: =SUMIFS(MOVIMENTACOES!F:F,MOVIMENTACOES!C:C,A48,MOVIMENTACOES!E:E,"Saída") -> 5 | G48: =E48-F48 -> 2 | H48: =IF(G48=0, "Faltando", IF(G48<=3, "Atenção", "OK")) -> Atenção
A49: 200000095 | B49: =VLOOKUP(A49,produto,2,0) -> ENDURECEDOR PARA RESINA | C49: =IFERROR(VLOOKUP(A49,PRODUTOS!A:E,5,FALSE), "Categoria não encontrada") -> ORTESES E PROTESES | D49: =IFERROR(VLOOKUP(A49,PRODUTOS!A:E,4,FALSE), "Categoria não encontrada") -> UN | E49: =SUMIFS(MOVIMENTACOES!F:F,MOVIMENTACOES!C:C,A49,MOVIMENTACOES!E:E,"Entrada") -> 2 | F49: =SUMIFS(MOVIMENTACOES!F:F,MOVIMENTACOES!C:C,A49,MOVIMENTACOES!E:E,"Saída") -> 1 | G49: =E49-F49 -> 1 | H49: =IF(G49=0, "Faltando", IF(G49<=3, "Atenção", "OK")) -> Atenção | I49: =VLOOKUP(A49, PRODUTOS!A:H, 3, FALSE) -> SES - Secretaria de Estado da Saude
A50: 200000091 | B50: =VLOOKUP(A50,produto,2,0) -> (MTA-20)MALHA ORTOPEDICA TUBULAR EM FIO DE ALGODÃO 20cm | C50: =IFERROR(VLOOKUP(A50,PRODUTOS!A:E,5,FALSE), "Categoria não encontrada") -> ORTESES E PROTESES | D50: =IFERROR(VLOOKUP(A50,PRODUTOS!A:E,4,FALSE), "Categoria não encontrada") -> UN | E50: =SUMIFS(MOVIMENTACOES!F:F,MOVIMENTACOES!C:C,A50,MOVIMENTACOES!E:E,"Entrada") -> 2 | F50: =SUMIFS(MOVIMENTACOES!F:F,MOVIMENTACOES!C:C,A50,MOVIMENTACOES!E:E,"Saída") -> 0 | G50: =E50-F50 -> 2 | H50: =IF(G50=0, "Faltando", IF(G50<=3, "Atenção", "OK")) -> Atenção | I50: =VLOOKUP(A50, PRODUTOS!A:H, 3, FALSE) -> SES - Secretaria de Estado da Saude
A51: 200000066 | B51: =VLOOKUP(A51,produto,2,0) -> ATADURA GESSADA 15cm x 3m, cx com 20 und | C51: =IFERROR(VLOOKUP(A51,PRODUTOS!A:E,5,FALSE), "Categoria não encontrada") -> ORTESES E PROTESES | D51: =IFERROR(VLOOKUP(A51,PRODUTOS!A:E,4,FALSE), "Categoria não encontrada") -> CX | E51: =SUMIFS(MOVIMENTACOES!F:F,MOVIMENTACOES!C:C,A51,MOVIMENTACOES!E:E,"Entrada") -> 12 | F51: =SUMIFS(MOVIMENTACOES!F:F,MOVIMENTACOES!C:C,A51,MOVIMENTACOES!E:E,"Saída") -> 9 | G51: =E51-F51 -> 3 | H51: =IF(G51=0, "Faltando", IF(G51<=3, "Atenção", "OK")) -> Atenção | I51: =VLOOKUP(A51, PRODUTOS!A:H, 3, FALSE)
A52: 200000065 | B52: =VLOOKUP(A52,produto,2,0) -> ATADURA GESSADA 20cm x 4m, cx com 20 und | C52: =IFERROR(VLOOKUP(A52,PRODUTOS!A:E,5,FALSE), "Categoria não encontrada") -> ORTESES E PROTESES | D52: =IFERROR(VLOOKUP(A52,PRODUTOS!A:E,4,FALSE), "Categoria não encontrada") -> CX | E52: =SUMIFS(MOVIMENTACOES!F:F,MOVIMENTACOES!C:C,A52,MOVIMENTACOES!E:E,"Entrada") -> 7 | F52: =SUMIFS(MOVIMENTACOES!F:F,MOVIMENTACOES!C:C,A52,MOVIMENTACOES!E:E,"Saída") -> 5 | G52: =E52-F52 -> 2 | H52: =IF(G52=0, "Faltando", IF(G52<=3, "Atenção", "OK")) -> Atenção | I52: =VLOOKUP(A52, PRODUTOS!A:H, 3, FALSE)
...
